Workbook

Sheet Instrucciones
A1: FP-180 — Matriz comparativa y cálculo de resultados (TINV-05 / FP-51)
A3: Estado: Motor de cálculo terminado y validado contra el ejemplo sintético de FP-177. Las 17 herramientas de la población de FP-51/FP-179 están investigadas con evidencia real, citada e individual, en sus escenarios elegibles: 5 herramientas cloud nativas (AWS Cost Explorer, AWS Cost Optimization Hub, Azure Cost Management, Google Cloud Billing, Google Cloud FinOps Hub), 6 plataformas multicloud (Cloudability, CloudHealth, CloudZero, Vantage, Finout, nOps), 4 herramientas de Kubernetes (OpenCost, Kubecost, Cast AI, StormForge) y 2 de estimación temprana (Infracost, Cloud Custodian). Documento estructurado con asistencia de IA; queda a validación humana del equipo antes de dar por cumplidos los criterios de término de FP-180.
A5: Este libro aplica, como fórmulas reproducibles de Excel, la metodología aprobada en docs/fp-177/metodologia-comparativa-borrador.md y la matriz de indicadores de docs/fp-177/matriz-criterios-y-ponderaciones-borrador.md. No sustituye esos documentos: ante cualquier discrepancia, prevalece el texto aprobado por el equipo.
A7: Límite metodológico de esta investigación: la verificación se hizo contra documentación oficial publicada, sin acceso práctico a una cuenta real de AWS/Azure/GCP ni a las consolas de los productos comerciales. Por eso ningún indicador recibe el valor 3: la metodología exige doble evidencia (documentación primaria + estudio independiente, demostración reproducible o verificación práctica del equipo) para ese valor, y aquí solo se dispone de la primera. El equipo puede subir cualquier valor a 3 si aporta esa segunda evidencia.
A9: Dos limitaciones puntuales quedan registradas para revisión del equipo: (1) la documentación técnica oficial de IBM Docs para Cloudability devolvió error 403 en todos los intentos de acceso durante esta investigación (2026-09-16); toda su evidencia proviene de páginas comerciales de apptio.com, por lo que, según la propia metodología, ningún indicador de Cloudability supera el valor 1 (ver columna Notas de sus filas). (2) Cloud Custodian está incluido en la población de FP-179 dentro de "herramientas de estimación temprana" (escenario E4), pero la evidencia oficial revisada muestra que es un motor de políticas/remediación sobre recursos YA desplegados, no una herramienta que estime costo antes del despliegue como Infracost; sus indicadores de Precio (P1, P2) y Visibilidad/Asignación se marcaron NA con esa justificación explícita, y se deja anotado por si el equipo prefiere revisar su clasificación en la población.
A11: Hojas de este libro:
A12: • Pesos — pesos de línea base y de sensibilidad por criterio (editable; todo el cálculo lee de aquí).
A13: • Puntuacion — una fila por Escenario x Producto x Indicador. Columnas: Valor (0-3/NE/NA), tipo de evidencia, evidencia, fuente, fecha de verificación y notas. Editar aquí para cargar nueva evidencia.
A14: • Calculo — una fila por Escenario x Producto. Calcula C_c por criterio, cobertura, renormalización, S (línea base y sensibilidad), banda e incumplimientos críticos, mediante fórmulas que leen directamente de Puntuacion y Pesos. No escribir valores fijos en esta hoja.
A15: • Graficos — gráficos de barras (S por producto y escenario) vinculados a la hoja Calculo.
A17: Reglas de puntuación (resumen; ver metodologia-comparativa-borrador.md para el detalle):
A18: • Escala 0-3: 0 ausencia/incumplimiento verificado; 1 práctica básica/manual; 2 práctica definida y proactiva; 3 práctica integrada y automatizada con doble evidencia.
... A27: Cruce con los papers académicos de FP-48 (revisión explícita a pedido del equipo): se revisaron los 13 PDF de "FP-48 TINV02/Papers academicos - FP-48/". Solo un paper nombra herramientas de la población de FP-51 -- Manurung y Aji (2025), que registra a 6 organizaciones reales usando AWS Cost Explorer, Cast.ai e Infracost, y encuentra que el 100% carece de showback/chargeback pese a ello. Según la propia metodología de FP-177 ("se excluye inferir resultados de herramientas desde evidencia académica que estudia prácticas... no el producto evaluado"), esa evidencia describe uso y brechas organizacionales, no verifica una capacidad del producto: se registró como nota de contexto en las filas de Puntuacion (columna Notas) para AWS Cost Explorer y se reutilizará para Cast AI / Infracost, pero no cambia ningún puntaje numérico. Los demás 12 papers ya están reflejados en docs/fp-177/ (metodología, criterios y escenarios) y no nombran productos comerciales adicionales.

Sheet Pesos
A1: Criterio | B1: Peso linea base (%) | C1: Peso sensibilidad (%)
A2: Visibilidad | B2: 11.111111 | C2: 15
A3: Asignación | B3: 11.111111 | C3: 15
A4: Optimización | B4: 11.111111 | C4: 15
A5: Automatización | B5: 11.111111 | C5: 10
A6: Multicloud | B6: 11.111111 | C6: 8
A7: Integración | B7: 11.111111 | C7: 10
A8: Adopción | B8: 11.111111 | C8: 8
A9: Precio | B9: 11.111111 | C9: 12
A10: Dependencia | B10: 11.111111 | C10: 7
A11: Total | B11: =SUM(B2:B10) | C11: =SUM(C2:C10)

Sheet Puntuacion
A1: Escenario | B1: Categoria | C1: Producto | D1: Criterio | E1: Indicador | F1: Pregunta observable | G1: Valor (0-3/NE/NA) | H1: Tipo de evidencia | I1: Evidencia | J1: Fuente | K1: Fecha de verificacion | L1: Notas
A2: E1 | B2: Cloud nativa | C2: AWS Cost Explorer | D2: Visibilidad | E2: V1 | F2: ¿Desagrega costo y uso por cuenta/proyecto, servicio y período? | G2: 2 | H2: Oficial | I2: Las etiquetas de asignación de costos y las Cost Categories desglosan el gasto por cuenta/proyecto y servicio, y son filtrables en Cost Explorer ("You can also use tags to filter views in Cost Explorer"). La actualización tiene hasta 24 h de latencia, no es en tiempo real. | J2: https://docs.aws.amazon.com/awsaccountbilling/latest/aboutv2/cost-alloc-tags.html | K2: 2026-09-16
A3: E1 | B3: Cloud nativa | C3: AWS Cost Explorer | D3: Visibilidad | E3: V2 | F3: ¿Permite rastrear un total hasta registros o fuente de facturación? | G3: 2 | H3: Oficial | I3: El Cost and Usage Report (CUR) entrega detalle por línea de facturación y "reconciles with the total charges on your Bills page", permitiendo rastrear un total hasta el registro fuente. | J3: https://docs.aws.amazon.com/cur/latest/userguide/what-is-cur.html | K3: 2026-09-16
A4: E1 | B4: Cloud nativa | C4: AWS Cost Explorer | D4: Asignacion | E4: A1 | F4: ¿Calcula gasto asignado/no asignado por responsable, centro o entidad? | G4: 2 | H4: Oficial | I4: Cost Categories es "a cost allocation service to help you map your AWS costs to your unique internal business structures" mediante reglas; expone una categoría de costos no mapeados. | J4: https://docs.aws.amazon.com/awsaccountbilling/latest/aboutv2/manage-cost-categories.html | K4: 2026-09-16 | L4: Contexto académico (no usado para puntuar): Manurung y Aji (2025) entrevistaron a 6 organizaciones que usan explícitamente esta herramienta ("We use AWS Cost Explorer, cast.ai, and infracost.", P2) y encontraron que el 100% (6/6) carece de showback/chargeback pese a ello ("[Gap] Cost ownership is centralized, no showback/chargeback", Tabla 4). Es evidencia de brecha organizacional, no de una limitación verificada del producto; se deja como insumo para el análisis de sensibilidad/limitaciones de FP-181, no como ajuste de este puntaje.
A5: E1 | B5: Cloud nativa | C5: AWS Cost Explorer | D5: Asignacion | E5: A2 | F5: ¿Explicita y aplica reglas para costo compartido/multi-tenant? | G5: 2 | H5: Oficial | I5: Cost Categories admite "Splitting charges within cost categories" (split charge rules) para repartir costos compartidos entre categorías/equipos. | J5: https://docs.aws.amazon.com/awsaccountbilling/latest/aboutv2/manage-cost-categories.html | K5: 2026-09-16
A6: E1 | B6: Cloud nativa | C6: AWS Cost Explorer | D6: Optimizacion | E6: O1 | F6: ¿Detecta desperdicio, rightsizing o compromiso relevante al escenario? | G6: 1 | H6: Oficial | I6: Cost Explorer conserva una vista propia de "rightsizing recommendations" (principalmente EC2), de alcance más acotado que Cost Optimization Hub. | J6: https://docs.aws.amazon.com/cost-management/latest/userguide/ce-rightsizing.html | K6: 2026-09-16
A7: E1 | B7: Cloud nativa | C7: AWS Cost Explorer | D7: Optimizacion | E7: O2 | F7: ¿Explica supuesto/impacto y permite seguir una recomendación? | G7: 1 | H7: Oficial | I7: La vista de rightsizing de Cost Explorer muestra el ahorro estimado por recomendación, sin el ciclo de seguimiento/objetivos que sí documenta Cost Optimization Hub. | J7: https://docs.aws.amazon.com/cost-management/latest/userguide/ce-rightsizing.html | K7: 2026-09-16
A8: E1 | B8: Cloud nativa | C8: AWS Cost Explorer | D8: Automatizacion | E8: AU1 | F8: ¿Ejecuta o bloquea acciones/políticas de costo con control verificable? | G8: 2 | H8: Oficial | I8: AWS Budgets puede ejecutar "budget actions" (política IAM Deny, SCP, detener instancias EC2/RDS) "either automatically or after your manual approval". | J8: https://docs.aws.amazon.com/cost-management/latest/userguide/budgets-controls.html | K8: 2026-09-16
A9: E1 | B9: Cloud nativa | C9: AWS Cost Explorer | D9: Automatizacion | E9: AU2 | F9: ¿Ofrece aprobación, reversión, registro o límites antes de actuar? | G9: 2 | H9: Oficial | I9: Las budget actions permiten exigir aprobación manual antes de ejecutarse. La documentación revisada no detalla registro de auditoría ni mecanismo de reversión explícito (limitación registrada). | J9: https://docs.aws.amazon.com/cost-management/latest/userguide/budgets-controls.html | K9: 2026-09-16
A10: E1 | B10: Cloud nativa | C10: AWS Cost Explorer | D10: Multicloud | E10: M1 | F10: ¿Consolida al menos dos proveedores bajo el mismo esquema declarado? | G10: 0 | H10: Oficial | I10: Cost Explorer y el CUR cubren exclusivamente cuentas y facturación de AWS; no ingieren ni consolidan datos de Azure o GCP. | J10: https://docs.aws.amazon.com/cur/latest/userguide/what-is-cur.html | K10: 2026-09-16
A11: E1 | B11: Cloud nativa | C11: AWS Cost Explorer | D11: Multicloud | E11: M2 | F11: ¿Hace visibles proveedor, cobertura y diferencias semánticas? | G11: 0 | H11: Oficial | I11: Al no consolidar otros proveedores, la herramienta no expone diferencias de cobertura o semántica entre nubes. | J11: https://docs.aws.amazon.com/cur/latest/userguide/what-is-cur.html | K11: 2026-09-16
A12: E1 | B12: Cloud nativa | C12: AWS Cost Explorer | D12: Integracion | E12: I1 | F12: ¿Integra datos requeridos (facturación, uso, clúster o IaC) del escenario? | G12: 2 | H12: Oficial | I12: El CUR/la API de Cost Explorer ingieren datos de facturación y uso de forma automatizada; para EKS, "Split Cost Allocation Data" añade métricas de clúster a nivel de pod/namespace al CUR. | J12: https://aws.amazon.com/about-aws/whats-new/2024/04/aws-split-cost-allocation-data-amazon-eks/ | K12: 2026-09-16
A13: E1 | B13: Cloud nativa | C13: AWS Cost Explorer | D13: Integracion | E13: I2 | F13: ¿Se integra con el flujo de trabajo relevante (alerta, ticket, CI/CD o reporte)? | G13: 2 | H13: Oficial | I13: AWS Cost Anomaly Detection y Budgets envían alertas (p. ej., a SNS/correo) integradas a un flujo operativo de revisión. | J13: https://docs.aws.amazon.com/cost-management/latest/userguide/budgets-controls.html | K13: 2026-09-16
A14: E1 | B14: Cloud nativa | C14: AWS Cost Explorer | D14: Adopcion | E14: AD1 | F14: ¿Soporta acceso/entrega para los roles del escenario? | G14: 2 | H14: Oficial (control de acceso IAM; pendiente cita directa de la guía de permisos de Billing) | I14: El acceso a Cost Explorer/Budgets se controla mediante políticas de IAM por usuario/rol (control de acceso estándar de AWS Billing). | J14: https://docs.aws.amazon.com/awsaccountbilling/latest/aboutv2/cost-alloc-tags.html | K14: 2026-09-16
A15: E1 | B15: Cloud nativa | C15: AWS Cost Explorer | D15: Adopcion | E15: AD2 | F15: ¿Ofrece guías, ownership o mecanismos de seguimiento para uso sostenido? | G15: 2 | H15: Oficial | I15: AWS publica guías oficiales de adopción, entre ellas el whitepaper de mejores prácticas de etiquetado y estrategia de asignación de costos. | J15: https://docs.aws.amazon.com/whitepapers/latest/tagging-best-practices/building-a-cost-allocation-strategy.html | K15: 2026-09-16 | L15: Contexto académico (no usado para puntuar): Manurung y Aji (2025) entrevistaron a 6 organizaciones que usan explícitamente esta herramienta ("We use AWS Cost Explorer, cast.ai, and infracost.", P2) y encontraron que el 100% (6/6) carece de showback/chargeback pese a ello ("[Gap] Cost ownership is centralized, no showback/chargeback", Tabla 4). Es evidencia de brecha organizacional, no de una limitación verificada del producto; se deja como insumo para el análisis de sensibilidad/limitaciones de FP-181, no como ajuste de este puntaje.
A16: E1 | B16: Cloud nativa | C16: AWS Cost Explorer | D16: Precio | E16: P1 | F16: ¿Expone precio, moneda, región, unidad, período y supuestos relevantes? | G16: 2 | H16: Oficial | I16: El CUR y los Data Exports FOCUS 1.0/1.2 exponen moneda, período, servicio y columnas estandarizadas de costo (ListCost, ContractedCost, BilledCost, EffectiveCost). | J16: https://aws.amazon.com/about-aws/whats-new/2024/11/aws-billing-cost-management-data-exports-focus-1-0 | K16: 2026-09-16
A17: E1 | B17: Cloud nativa | C17: AWS Cost Explorer | D17: Precio | E17: P2 | F17: ¿Permite estimar o comparar componentes sin ocultar límites de equivalencia? | G17: 1 | H17: Oficial (pendiente cita directa de la página de forecast) | I17: Cost Explorer ofrece pronóstico de costo futuro basado en tendencia histórica; no es una calculadora de estimación de componentes antes del despliegue (esa función es de AWS Pricing Calculator, evaluada aparte). | J17: https://docs.aws.amazon.com/cost-management/latest/userguide/ce-what-is.html | K17: 2026-09-16
A18: E1 | B18: Cloud nativa | C18: AWS Cost Explorer | D18: Dependencia | E18: D1 | F18: ¿Exporta datos/resultados en formato utilizable y documentado? | G18: 2 | H18: Oficial | I18: El CUR exporta a S3 en CSV/Parquet y, desde 2024-2025, también en el estándar abierto FOCUS 1.0/1.2. | J18: https://aws.amazon.com/about-aws/whats-new/2024/11/aws-billing-cost-management-data-exports-focus-1-0 | K18: 2026-09-16
A19: E1 | B19: Cloud nativa | C19: AWS Cost Explorer | D19: Dependencia | E19: D2 | F19: ¿Documenta dependencias propietarias y un camino de salida/configuración reversible? | G19: 1 | H19: Oficial | I19: No se encontró documentación específica de un "camino de salida" dedicado. El riesgo de dependencia es menor porque los datos son exportables en formato estándar (FOCUS) y el servicio no tiene costo propio, pero no hay guía de reversibilidad dedicada (limitación registrada). | J19: https://aws.amazon.com/about-aws/whats-new/2024/11/aws-billing-cost-management-data-exports-focus-1-0 | K19: 2026-09-16
A20: E2 | B20: Cloud nativa | C20: AWS Cost Explorer | D20: Visibilidad | E20: V1 | F20: ¿Desagrega costo y uso por cuenta/proyecto, servicio y período? | G20: NE | H20: Pendiente | I20: Las etiquetas de asignación de costos y las Cost Categories desglosan el gasto por cuenta/proyecto y servicio, y son filtrables en Cost Explorer ("You can also use tags to filter views in Cost Explorer"). La actualización tiene hasta 24 h de latencia, no es en tiempo real. | J20: https://docs.aws.amazon.com/awsaccountbilling/latest/aboutv2/cost-alloc-tags.html | K20: 2026-09-16 | L20: Celda heredada FP-180 (2026-09-16): el valor 2 proviene de la investigacion del escenario E1 y no cuenta con evidencia propia de E2. Segun FP-177 el indicador V1 depende del escenario, por lo que pasa a NE (no evidenciado, reduce cobertura) hasta investigarlo. La evidencia y la fuente originales se conservan como referencia del escenario de origen.
A21: E2 | B21: Cloud nativa | C21: AWS Cost Explorer | D21: Visibilidad | E21: V2 | F21: ¿Permite rastrear un total hasta registros o fuente de facturación? | G21: 2 | H21: Oficial | I21: El Cost and Usage Report (CUR) entrega detalle por línea de facturación y "reconciles with the total charges on your Bills page", permitiendo rastrear un total hasta el registro fuente. | J21: https://docs.aws.amazon.com/cur/latest/userguide/what-is-cur.html | K21: 2026-09-16
A22: E2 | B22: Cloud nativa | C22: AWS Cost Explorer | D22: Asignacion | E22: A1 | F22: ¿Calcula gasto asignado/no asignado por responsable, centro o entidad? | G22: NE | H22: Pendiente | I22: Cost Categories es "a cost allocation service to help you map your AWS costs to your unique internal business structures" mediante reglas; expone una categoría de costos no mapeados. | J22: https://docs.aws.amazon.com/awsaccountbilling/latest/aboutv2/manage-cost-categories.html | K22: 2026-09-16 | L22: Contexto académico (no usado para puntuar): Manurung y Aji (2025) entrevistaron a 6 organizaciones que usan explícitamente esta herramienta ("We use AWS Cost Explorer, cast.ai, and infracost.", P2) y encontraron que el 100% (6/6) carece de showback/chargeback pese a ello ("[Gap] Cost ownership is centralized, no showback/chargeback", Tabla 4). Es evidencia de brecha organizacional, no de una limitación verificada del producto; se deja como insumo para el análisis de sensibilidad/limitaciones de FP-181, no como ajuste de este puntaje. | Celda heredada FP-180 (2026-09-16): el valor 2 proviene de la investigacion del escenario E1 y no cuenta con evidencia propia de E2. Segun FP-177 el indicador A1 depende del escenario, por lo que pasa a NE (no evidenciado, reduce cobertura) hasta investigarlo. La evidencia y la fuente originales se conservan como referencia del escenario de origen.
A23: E2 | B23: Cloud nativa | C23: AWS Cost Explorer | D23: Asignacion | E23: A2 | F23: ¿Explicita y aplica reglas para costo compartido/multi-tenant? | G23: NE | H23: Pendiente | I23: Cost Categories admite "Splitting charges within cost categories" (split charge rules) para repartir costos compartidos entre categorías/equipos. | J23: https://docs.aws.amazon.com/awsaccountbilling/latest/aboutv2/manage-cost-categories.html | K23: 2026-09-16 | L23: Celda heredada FP-180 (2026-09-16): el valor 2 proviene de la investigacion del escenario E1 y no cuenta con evidencia propia de E2. Segun FP-177 el indicador A2 depende del escenario, por lo que pasa a NE (no evidenciado, reduce cobertura) hasta investigarlo. La evidencia y la fuente originales se conservan como referencia del escenario de origen.
A24: E2 | B24: Cloud nativa | C24: AWS Cost Explorer | D24: Optimizacion | E24: O1 | F24: ¿Detecta desperdicio, rightsizing o compromiso relevante al escenario? | G24: NE | H24: Pendiente | I24: Cost Explorer conserva una vista propia de "rightsizing recommendations" (principalmente EC2), de alcance más acotado que Cost Optimization Hub. | J24: https://docs.aws.amazon.com/cost-management/latest/userguide/ce-rightsizing.html | K24: 2026-09-16 | L24: Celda heredada FP-180 (2026-09-16): el valor 1 proviene de la investigacion del escenario E1 y no cuenta con evidencia propia de E2. Segun FP-177 el indicador O1 depende del escenario, por lo que pasa a NE (no evidenciado, reduce cobertura) hasta investigarlo. La evidencia y la fuente originales se conservan como referencia del escenario de origen.
A25: E2 | B25: Cloud nativa | C25: AWS Cost Explorer | D25: Optimizacion | E25: O2 | F25: ¿Explica supuesto/impacto y permite seguir una recomendación? | G25: 1 | H25: Oficial | I25: La vista de rightsizing de Cost Explorer muestra el ahorro estimado por recomendación, sin el ciclo de seguimiento/objetivos que sí documenta Cost Optimization Hub. | J25: https://docs.aws.amazon.com/cost-management/latest/userguide/ce-rightsizing.html | K25: 2026-09-16
A26: E2 | B26: Cloud nativa | C26: AWS Cost Explorer | D26: Automatizacion | E26: AU1 | F26: ¿Ejecuta o bloquea acciones/políticas de costo con control verificable? | G26: NE | H26: Pendiente | I26: AWS Budgets puede ejecutar "budget actions" (política IAM Deny, SCP, detener instancias EC2/RDS) "either automatically or after your manual approval". | J26: https://docs.aws.amazon.com/cost-management/latest/userguide/budgets-controls.html | K26: 2026-09-16 | L26: Celda heredada FP-180 (2026-09-16): el valor 2 proviene de la investigacion del escenario E1 y no cuenta con evidencia propia de E2. Segun FP-177 el indicador AU1 depende del escenario, por lo que pasa a NE (no evidenciado, reduce cobertura) hasta investigarlo. La evidencia y la fuente originales se conservan como referencia del escenario de origen.
A27: E2 | B27: Cloud nativa | C27: AWS Cost Explorer | D27: Automatizacion | E27: AU2 | F27: ¿Ofrece aprobación, reversión, registro o límites antes de actuar? | G27: 2 | H27: Oficial | I27: Las budget actions permiten exigir aprobación manual antes de ejecutarse. La documentación revisada no detalla registro de auditoría ni mecanismo de reversión explícito (limitación registrada). | J27: https://docs.aws.amazon.com/cost-management/latest/userguide/budgets-controls.html | K27: 2026-09-16
A28: E2 | B28: Cloud nativa | C28: AWS Cost Explorer | D28: Multicloud | E28: M1 | F28: ¿Consolida al menos dos proveedores bajo el mismo esquema declarado? | G28: 0 | H28: Oficial | I28: Cost Explorer y el CUR cubren exclusivamente cuentas y facturación de AWS; no ingieren ni consolidan datos de Azure o GCP. | J28: https://docs.aws.amazon.com/cur/latest/userguide/what-is-cur.html | K28: 2026-09-16
A29: E2 | B29: Cloud nativa | C29: AWS Cost Explorer | D29: Multicloud | E29: M2 | F29: ¿Hace visibles proveedor, cobertura y diferencias semánticas? | G29: 0 | H29: Oficial | I29: Al no consolidar otros proveedores, la herramienta no expone diferencias de cobertura o semántica entre nubes. | J29: https://docs.aws.amazon.com/cur/latest/userguide/what-is-cur.html | K29: 2026-09-16
A30: E2 | B30: Cloud nativa | C30: AWS Cost Explorer | D30: Integracion | E30: I1 | F30: ¿Integra datos requeridos (facturación, uso, clúster o IaC) del escenario? | G30: NE | H30: Pendiente | I30: El CUR/la API de Cost Explorer ingieren datos de facturación y uso de forma automatizada; para EKS, "Split Cost Allocation Data" añade métricas de clúster a nivel de pod/namespace al CUR. | J30: https://aws.amazon.com/about-aws/whats-new/2024/04/aws-split-cost-allocation-data-amazon-eks/ | K30: 2026-09-16 | L30: Celda heredada FP-180 (2026-09-16): el valor 2 proviene de la investigacion del escenario E1 y no cuenta con evidencia propia de E2. Segun FP-177 el indicador I1 depende del escenario, por lo que pasa a NE (no evidenciado, reduce cobertura) hasta investigarlo. La evidencia y la fuente originales se conservan como referencia del escenario de origen.
A31: E2 | B31: Cloud nativa | C31: AWS Cost Explorer | D31: Integracion | E31: I2 | F31: ¿Se integra con el flujo de trabajo relevante (alerta, ticket, CI/CD o reporte)? | G31: NE | H31: Pendiente | I31: AWS Cost Anomaly Detection y Budgets envían alertas (p. ej., a SNS/correo) integradas a un flujo operativo de revisión. | J31: https://docs.aws.amazon.com/cost-management/latest/userguide/budgets-controls.html | K31: 2026-09-16 | L31: Celda heredada FP-180 (2026-09-16): el valor 2 proviene de la investigacion del escenario E1 y no cuenta con evidencia propia de E2. Segun FP-177 el indicador I2 depende del escenario, por lo que pasa a NE (no evidenciado, reduce cobertura) hasta investigarlo. La evidencia y la fuente originales se conservan como referencia del escenario de origen.
A32: E2 | B32: Cloud nativa | C32: AWS Cost Explorer | D32: Adopcion | E32: AD1 | F32: ¿Soporta acceso/entrega para los roles del escenario? | G32: NE | H32: Pendiente | I32: El acceso a Cost Explorer/Budgets se controla mediante políticas de IAM por usuario/rol (control de acceso estándar de AWS Billing). | J32: https://docs.aws.amazon.com/awsaccountbilling/latest/aboutv2/cost-alloc-tags.html | K32: 2026-09-16 | L32: Celda heredada FP-180 (2026-09-16): el valor 2 proviene de la investigacion del escenario E1 y no cuenta con evidencia propia de E2. Segun FP-177 el indicador AD1 depende del escenario, por lo que pasa a NE (no evidenciado, reduce cobertura) hasta investigarlo. La evidencia y la fuente originales se conservan como referencia del escenario de origen.
A33: E2 | B33: Cloud nativa | C33: AWS Cost Explorer | D33: Adopcion | E33: AD2 | F33: ¿Ofrece guías, ownership o mecanismos de seguimiento para uso sostenido? | G33: 2 | H33: Oficial | I33: AWS publica guías oficiales de adopción, entre ellas el whitepaper de mejores prácticas de etiquetado y estrategia de asignación de costos. | J33: https://docs.aws.amazon.com/whitepapers/latest/tagging-best-practices/building-a-cost-allocation-strategy.html | K33: 2026-09-16 | L33: Contexto académico (no usado para puntuar): Manurung y Aji (2025) entrevistaron a 6 organizaciones que usan explícitamente esta herramienta ("We use AWS Cost Explorer, cast.ai, and infracost.", P2) y encontraron que el 100% (6/6) carece de showback/chargeback pese a ello ("[Gap] Cost ownership is centralized, no showback/chargeback", Tabla 4). Es evidencia de brecha organizacional, no de una limitación verificada del producto; se deja como insumo para el análisis de sensibilidad/limitaciones de FP-181, no como ajuste de este puntaje.
A34: E2 | B34: Cloud nativa | C34: AWS Cost Explorer | D34: Precio | E34: P1 | F34: ¿Expone precio, moneda, región, unidad, período y supuestos relevantes? | G34: 2 | H34: Oficial | I34: El CUR y los Data Exports FOCUS 1.0/1.2 exponen moneda, período, servicio y columnas estandarizadas de costo (ListCost, ContractedCost, BilledCost, EffectiveCost). | J34: https://aws.amazon.com/about-aws/whats-new/2024/11/aws-billing-cost-management-data-exports-focus-1-0 | K34: 2026-09-16
A35: E2 | B35: Cloud nativa | C35: AWS Cost Explorer | D35: Precio | E35: P2 | F35: ¿Permite estimar o comparar componentes sin ocultar límites de equivalencia? | G35: NE | H35: Pendiente | I35: Cost Explorer ofrece pronóstico de costo futuro basado en tendencia histórica; no es una calculadora de estimación de componentes antes del despliegue (esa función es de AWS Pricing Calculator, evaluada aparte). | J35: https://docs.aws.amazon.com/cost-management/latest/userguide/ce-what-is.html | K35: 2026-09-16 | L35: Celda heredada FP-180 (2026-09-16): el valor 1 proviene de la investigacion del escenario E1 y no cuenta con evidencia propia de E2. Segun FP-177 el indicador P2 depende del escenario, por lo que pasa a NE (no evidenciado, reduce cobertura) hasta investigarlo. La evidencia y la fuente originales se conservan como referencia del escenario de origen.
A36: E2 | B36: Cloud nativa | C36: AWS Cost Explorer | D36: Dependencia | E36: D1 | F36: ¿Exporta datos/resultados en formato utilizable y documentado? | G36: 2 | H36: Oficial | I36: El CUR exporta a S3 en CSV/Parquet y, desde 2024-2025, también en el estándar abierto FOCUS 1.0/1.2. | J36: https://aws.amazon.com/about-aws/whats-new/2024/11/aws-billing-cost-management-data-exports-focus-1-0 | K36: 2026-09-16
A37: E2 | B37: Cloud nativa | C37: AWS Cost Explorer | D37: Dependencia | E37: D2 | F37: ¿Documenta dependencias propietarias y un camino de salida/configuración reversible? | G37: 1 | H37: Oficial | I37: No se encontró documentación específica de un "camino de salida" dedicado. El riesgo de dependencia es menor porque los datos son exportables en formato estándar (FOCUS) y el servicio no tiene costo propio, pero no hay guía de reversibilidad dedicada (limitación registrada). | J37: https://aws.amazon.com/about-aws/whats-new/2024/11/aws-billing-cost-management-data-exports-focus-1-0 | K37: 2026-09-16
A38: E3 | B38: Cloud nativa | C38: AWS Cost Explorer | D38: Visibilidad | E38: V1 | F38: ¿Desagrega costo y uso por cuenta/proyecto, servicio y período? | G38: NE | H38: Pendiente | I38: Las etiquetas de asignación de costos y las Cost Categories desglosan el gasto por cuenta/proyecto y servicio, y son filtrables en Cost Explorer ("You can also use tags to filter views in Cost Explorer"). La actualización tiene hasta 24 h de latencia, no es en tiempo real. | J38: https://docs.aws.amazon.com/awsaccountbilling/latest/aboutv2/cost-alloc-tags.html | K38: 2026-09-16 | L38: En E3, la evidencia de granularidad de clúster proviene de "Split Cost Allocation Data" para Amazon EKS (visibilidad a nivel de pod/namespace); las recomendaciones de rightsizing de AWS (Cost Explorer/Cost Optimization Hub) operan sobre el nodo EC2 subyacente, no sobre el dimensionamiento de pods dentro del clúster, lo que limita su alcance frente a herramientas especializadas en Kubernetes (OpenCost, Kubecost, Cast AI, StormForge). | Celda heredada FP-180 (2026-09-16): el valor 2 proviene de la investigacion del escenario E1 y no cuenta con evidencia propia de E3. Segun FP-177 el indicador V1 depende del escenario, por lo que pasa a NE (no evidenciado, reduce cobertura) hasta investigarlo. La evidencia y la fuente originales se conservan como referencia del escenario de origen.
A39: E3 | B39: Cloud nativa | C39: AWS Cost Explorer | D39: Visibilidad | E39: V2 | F39: ¿Permite rastrear un total hasta registros o fuente de facturación? | G39: 2 | H39: Oficial | I39: El Cost and Usage Report (CUR) entrega detalle por línea de facturación y "reconciles with the total charges on your Bills page", permitiendo rastrear un total hasta el registro fuente. | J39: https://docs.aws.amazon.com/cur/latest/userguide/what-is-cur.html | K39: 2026-09-16 | L39: En E3, la evidencia de granularidad de clúster proviene de "Split Cost Allocation Data" para Amazon EKS (visibilidad a nivel de pod/namespace); las recomendaciones de rightsizing de AWS (Cost Explorer/Cost Optimization Hub) operan sobre el nodo EC2 subyacente, no sobre el dimensionamiento de pods dentro del clúster, lo que limita su alcance frente a herramientas especializadas en Kubernetes (OpenCost, Kubecost, Cast AI, StormForge).
A40: E3 | B40: Cloud nativa | C40: AWS Cost Explorer | D40: Asignacion | E40: A1 | F40: ¿Calcula gasto asignado/no asignado por responsable, centro o entidad? | G40: NE | H40: Pendiente | I40: Cost Categories es "a cost allocation service to help you map your AWS costs to your unique internal business structures" mediante reglas; expone una categoría de costos no mapeados. | J40: https://docs.aws.amazon.com/awsaccountbilling/latest/aboutv2/manage-cost-categories.html | K40: 2026-09-16 | L40: En E3, la evidencia de granularidad de clúster proviene de "Split Cost Allocation Data" para Amazon EKS (visibilidad a nivel de pod/namespace); las recomendaciones de rightsizing de AWS (Cost Explorer/Cost Optimization Hub) operan sobre el nodo EC2 subyacente, no sobre el dimensionamiento de pods dentro del clúster, lo que limita su alcance frente a herramientas especializadas en Kubernetes (OpenCost, Kubecost, Cast AI, StormForge). Contexto académico (no usado para puntuar): Manurung y Aji (2025) entrevistaron a 6 organizaciones que usan explícitamente esta herramienta ("We use AWS Cost Explorer, cast.ai, and infracost.", P2) y encontraron que el 100% (6/6) carece de showback/chargeback pese a ello ("[Gap] Cost ownership is centralized, no showback/chargeback", Tabla 4). Es evidencia de brecha organizacional, no de una limitación verificada del producto; se deja como insumo para el análisis de sensibilidad/limitaciones de FP-181, no como ajuste de este puntaje. | Celda heredada FP-180 (2026-09-16): el valor 2 proviene de la investigacion del escenario E1 y no cuenta con evidencia propia de E3. Segun FP-177 el indicador A1 depende del escenario, por lo que pasa a NE (no evidenciado, reduce cobertura) hasta investigarlo. La evidencia y la fuente originales se conservan como referencia del escenario de origen.
...

Sheet Calculo
A1: Escenario | B1: Categoria | C1: Producto | D1: Visibilidad - Aplicable | E1: Visibilidad - Evidenciado | F1: Visibilidad - C_c | G1: Asignación - Aplicable | H1: Asignación - Evidenciado | I1: Asignación - C_c | J1: Optimización - Aplicable | K1: Optimización - Evidenciado | L1: Optimización - C_c | M1: Automatización - Aplicable | N1: Automatización - Evidenciado | O1: Automatización - C_c | P1: Multicloud - Aplicable | Q1: Multicloud - Evidenciado | R1: Multicloud - C_c | S1: Integración - Aplicable | T1: Integración - Evidenciado | U1: Integración - C_c | V1: Adopción - Aplicable | W1: Adopción - Evidenciado | X1: Adopción - C_c | Y1: Precio - Aplicable | Z1: Precio - Evidenciado | AA1: Precio - C_c | AB1: Dependencia - Aplicable | AC1: Dependencia - Evidenciado | AD1: Dependencia - C_c | AE1: Cobertura base (%) | AF1: Cobertura sensibilidad (%) | AG1: S linea base (0-100) | AH1: S sensibilidad (0-100) | AI1: Banda linea base | AJ1: Banda sensibilidad | AK1: Criterios criticos incumplidos (C_c<1)
A2: E1 | B2: Cloud nativa | C2: AWS Cost Explorer | D2: =IF(COUNTIFS(Puntuacion!$A:$A,$A2,Puntuacion!$C:$C,$C2,Puntuacion!$D:$D,"Visibilidad",Puntuacion!$G:$G,"<>NA")>0,1,0) | E2: =IF(AND(D2=1,COUNTIFS(Puntuacion!$A:$A,$A2,Puntuacion!$C:$C,$C2,Puntuacion!$D:$D,"Visibilidad",Puntuacion!$G:$G,"NE")=0),1,0) | F2: =IF(D2=0,"NA",IF(E2=0,"NE",AVERAGEIFS(Puntuacion!$G:$G,Puntuacion!$A:$A,$A2,Puntuacion!$C:$C,$C2,Puntuacion!$D:$D,"Visibilidad",Puntuacion!$G:$G,"<>NA",Puntuacion!$G:$G,"<>NE"))) | G2: =IF(COUNTIFS(Puntuacion!$A:$A,$A2,Puntuacion!$C:$C,$C2,Puntuacion!$D:$D,"Asignacion",Puntuacion!$G:$G,"<>NA")>0,1,0) | H2: =IF(AND(G2=1,COUNTIFS(Puntuacion!$A:$A,$A2,Puntuacion!$C:$C,$C2,Puntuacion!$D:$D,"Asignacion",Puntuacion!$G:$G,"NE")=0),1,0) | I2: =IF(G2=0,"NA",IF(H2=0,"NE",AVERAGEIFS(Puntuacion!$G:$G,Puntuacion!$A:$A,$A2,Puntuacion!$C:$C,$C2,Puntuacion!$D:$D,"Asignacion",Puntuacion!$G:$G,"<>NA",Puntuacion!$G:$G,"<>NE"))) | J2: =IF(COUNTIFS(Puntuacion!$A:$A,$A2,Puntuacion!$C:$C,$C2,Puntuacion!$D:$D,"Optimizacion",Puntuacion!$G:$G,"<>NA")>0,1,0) | K2: =IF(AND(J2=1,COUNTIFS(Puntuacion!$A:$A,$A2,Puntuacion!$C:$C,$C2,Puntuacion!$D:$D,"Optimizacion",Puntuacion!$G:$G,"NE")=0),1,0) | L2: =IF(J2=0,"NA",IF(K2=0,"NE",AVERAGEIFS(Puntuacion!$G:$G,Puntuacion!$A:$A,$A2,Puntuacion!$C:$C,$C2,Puntuacion!$D:$D,"Optimizacion",Puntuacion!$G:$G,"<>NA",Puntuacion!$G:$G,"<>NE"))) | M2: =IF(COUNTIFS(Puntuacion!$A:$A,$A2,Puntuacion!$C:$C,$C2,Puntuacion!$D:$D,"Automatizacion",Puntuacion!$G:$G,"<>NA")>0,1,0) | N2: =IF(AND(M2=1,COUNTIFS(Puntuacion!$A:$A,$A2,Puntuacion!$C:$C,$C2,Puntuacion!$D:$D,"Automatizacion",Puntuacion!$G:$G,"NE")=0),1,0) | O2: =IF(M2=0,"NA",IF(N2=0,"NE",AVERAGEIFS(Puntuacion!$G:$G,Puntuacion!$A:$A,$A2,Puntuacion!$C:$C,$C2,Puntuacion!$D:$D,"Automatizacion",Puntuacion!$G:$G,"<>NA",Puntuacion!$G:$G,"<>NE"))) | P2: =IF(COUNTIFS(Puntuacion!$A:$A,$A2,Puntuacion!$C:$C,$C2,Puntuacion!$D:$D,"Multicloud",Puntuacion!$G:$G,"<>NA")>0,1,0) | Q2: =IF(AND(P2=1,COUNTIFS(Puntuacion!$A:$A,$A2,Puntuacion!$C:$C,$C2,Puntuacion!$D:$D,"Multicloud",Puntuacion!$G:$G,"NE")=0),1,0) | R2: =IF(P2=0,"NA",IF(Q2=0,"NE",AVERAGEIFS(Puntuacion!$G:$G,Puntuacion!$A:$A,$A2,Puntuacion!$C:$C,$C2,Puntuacion!$D:$D,"Multicloud",Puntuacion!$G:$G,"<>NA",Puntuacion!$G:$G,"<>NE"))) | S2: =IF(COUNTIFS(Puntuacion!$A:$A,$A2,Puntuacion!$C:$C,$C2,Puntuacion!$D:$D,"Integracion",Puntuacion!$G:$G,"<>NA")>0,1,0) | T2: =IF(AND(S2=1,COUNTIFS(Puntuacion!$A:$A,$A2,Puntuacion!$C:$C,$C2,Puntuacion!$D:$D,"Integracion",Puntuacion!$G:$G,"NE")=0),1,0) | U2: =IF(S2=0,"NA",IF(T2=0,"NE",AVERAGEIFS(Puntuacion!$G:$G,Puntuacion!$A:$A,$A2,Puntuacion!$C:$C,$C2,Puntuacion!$D:$D,"Integracion",Puntuacion!$G:$G,"<>NA",Puntuacion!$G:$G,"<>NE"))) | V2: =IF(COUNTIFS(Puntuacion!$A:$A,$A2,Puntuacion!$C:$C,$C2,Puntuacion!$D:$D,"Adopcion",Puntuacion!$G:$G,"<>NA")>0,1,0) | W2: =IF(AND(V2=1,COUNTIFS(Puntuacion!$A:$A,$A2,Puntuacion!$C:$C,$C2,Puntuacion!$D:$D,"Adopcion",Puntuacion!$G:$G,"NE")=0),1,0) | X2: =IF(V2=0,"NA",IF(W2=0,"NE",AVERAGEIFS(Puntuacion!$G:$G,Puntuacion!$A:$A,$A2,Puntuacion!$C:$C,$C2,Puntuacion!$D:$D,"Adopcion",Puntuacion!$G:$G,"<>NA",Puntuacion!$G:$G,"<>NE"))) | Y2: =IF(COUNTIFS(Puntuacion!$A:$A,$A2,Puntuacion!$C:$C,$C2,Puntuacion!$D:$D,"Precio",Puntuacion!$G:$G,"<>NA")>0,1,0) | Z2: =IF(AND(Y2=1,COUNTIFS(Puntuacion!$A:$A,$A2,Puntuacion!$C:$C,$C2,Puntuacion!$D:$D,"Precio",Puntuacion!$G:$G,"NE")=0),1,0) | AA2: =IF(Y2=0,"NA",IF(Z2=0,"NE",AVERAGEIFS(Puntuacion!$G:$G,Puntuacion!$A:$A,$A2,Puntuacion!$C:$C,$C2,Puntuacion!$D:$D,"Precio",Puntuacion!$G:$G,"<>NA",Puntuacion!$G:$G,"<>NE"))) | AB2: =IF(COUNTIFS(Puntuacion!$A:$A,$A2,Puntuacion!$C:$C,$C2,Puntuacion!$D:$D,"Dependencia",Puntuacion!$G:$G,"<>NA")>0,1,0) | AC2: =IF(AND(AB2=1,COUNTIFS(Puntuacion!$A:$A,$A2,Puntuacion!$C:$C,$C2,Puntuacion!$D:$D,"Dependencia",Puntuacion!$G:$G,"NE")=0),1,0) | AD2: =IF(AB2=0,"NA",IF(AC2=0,"NE",AVERAGEIFS(Puntuacion!$G:$G,Puntuacion!$A:$A,$A2,Puntuacion!$C:$C,$C2,Puntuacion!$D:$D,"Dependencia",Puntuacion!$G:$G,"<>NA",Puntuacion!$G:$G,"<>NE"))) | AE2: =IFERROR(100*(E2*Pesos!$B$2+H2*Pesos!$B$3+K2*Pesos!$B$4+N2*Pesos!$B$5+Q2*Pesos!$B$6+T2*Pesos!$B$7+W2*Pesos!$B$8+Z2*Pesos!$B$9+AC2*Pesos!$B$10)/(D2*Pesos!$B$2+G2*Pesos!$B$3+J2*Pesos!$B$4+M2*Pesos!$B$5+P2*Pesos!$B$6+S2*Pesos!$B$7+V2*Pesos!$B$8+Y2*Pesos!$B$9+AB2*Pesos!$B$10),"Sin criterios aplicables") | AF2: =IFERROR(100*(E2*Pesos!$C$2+H2*Pesos!$C$3+K2*Pesos!$C$4+N2*Pesos!$C$5+Q2*Pesos!$C$6+T2*Pesos!$C$7+W2*Pesos!$C$8+Z2*Pesos!$C$9+AC2*Pesos!$C$10)/(D2*Pesos!$C$2+G2*Pesos!$C$3+J2*Pesos!$C$4+M2*Pesos!$C$5+P2*Pesos!$C$6+S2*Pesos!$C$7+V2*Pesos!$C$8+Y2*Pesos!$C$9+AB2*Pesos!$C$10),"Sin criterios aplicables") | AG2: =IF(OR(AE2="Sin criterios aplicables",AE2<70),"Insufficient evidence",100*(Pesos!$B$2*IF(E2=1,F2,0)+Pesos!$B$3*IF(H2=1,I2,0)+Pesos!$B$4*IF(K2=1,L2,0)+Pesos!$B$5*IF(N2=1,O2,0)+Pesos!$B$6*IF(Q2=1,R2,0)+Pesos!$B$7*IF(T2=1,U2,0)+Pesos!$B$8*IF(W2=1,X2,0)+Pesos!$B$9*IF(Z2=1,AA2,0)+Pesos!$B$10*IF(AC2=1,AD2,0))/(3*(Pesos!$B$2*E2+Pesos!$B$3*H2+Pesos!$B$4*K2+Pesos!$B$5*N2+Pesos!$B$6*Q2+Pesos!$B$7*T2+Pesos!$B$8*W2+Pesos!$B$9*Z2+Pesos!$B$10*AC2))) | AH2: =IF(OR(AF2="Sin criterios aplicables",AF2<70),"Insufficient evidence",100*(Pesos!$C$2*IF(E2=1,F2,0)+Pesos!$C$3*IF(H2=1,I2,0)+Pesos!$C$4*IF(K2=1,L2,0)+Pesos!$C$5*IF(N2=1,O2,0)+Pesos!$C$6*IF(Q2=1,R2,0)+Pesos!$C$7*IF(T2=1,U2,0)+Pesos!$C$8*IF(W2=1,X2,0)+Pesos!$C$9*IF(Z2=1,AA2,0)+Pesos!$C$10*IF(AC2=1,AD2,0))/(3*(Pesos!$C$2*E2+Pesos!$C$3*H2+Pesos!$C$4*K2+Pesos!$C$5*N2+Pesos!$C$6*Q2+Pesos!$C$7*T2+Pesos!$C$8*W2+Pesos!$C$9*Z2+Pesos!$C$10*AC2))) | AI2: =IF(AG2="Insufficient evidence","Insufficient evidence (cobertura<70%)",IF(AG2<50/3,"Insufficient",IF(AG2<50,"Basic",IF(AG2<250/3,"Solid","Advanced")))) | AJ2: =IF(AH2="Insufficient evidence","Insufficient evidence (cobertura<70%)",IF(AH2<50/3,"Insufficient",IF(AH2<50,"Basic",IF(AH2<250/3,"Solid","Advanced")))) | AK2: =IF(TRIM(IF(AND(ISNUMBER(F2),F2<1),"Visibilidad","") & " " & IF(AND(ISNUMBER(I2),I2<1),"Asignación",""))="","Ninguno",TRIM(IF(AND(ISNUMBER(F2),F2<1),"Visibilidad","") & " " & IF(AND(ISNUMBER(I2),I2<1),"Asignación","")))
A3: E1 | B3: Cloud nativa | C3: AWS Cost Optimization Hub | D3: =IF(COUNTIFS(Puntuacion!$A:$A,$A3,Puntuacion!$C:$C,$C3,Puntuacion!$D:$D,"Visibilidad",Puntuacion!$G:$G,"<>NA")>0,1,0) | E3: =IF(AND(D3=1,COUNTIFS(Puntuacion!$A:$A,$A3,Puntuacion!$C:$C,$C3,Puntuacion!$D:$D,"Visibilidad",Puntuacion!$G:$G,"NE")=0),1,0) | F3: =IF(D3=0,"NA",IF(E3=0,"NE",AVERAGEIFS(Puntuacion!$G:$G,Puntuacion!$A:$A,$A3,Puntuacion!$C:$C,$C3,Puntuacion!$D:$D,"Visibilidad",Puntuacion!$G:$G,"<>NA",Puntuacion!$G:$G,"<>NE"))) | G3: =IF(COUNTIFS(Puntuacion!$A:$A,$A3,Puntuacion!$C:$C,$C3,Puntuacion!$D:$D,"Asignacion",Puntuacion!$G:$G,"<>NA")>0,1,0) | H3: =IF(AND(G3=1,COUNTIFS(Puntuacion!$A:$A,$A3,Puntuacion!$C:$C,$C3,Puntuacion!$D:$D,"Asignacion",Puntuacion!$G:$G,"NE")=0),1,0) | I3: =IF(G3=0,"NA",IF(H3=0,"NE",AVERAGEIFS(Puntuacion!$G:$G,Puntuacion!$A:$A,$A3,Puntuacion!$C:$C,$C3,Puntuacion!$D:$D,"Asignacion",Puntuacion!$G:$G,"<>NA",Puntuacion!$G:$G,"<>NE"))) | J3: =IF(COUNTIFS(Puntuacion!$A:$A,$A3,Puntuacion!$C:$C,$C3,Puntuacion!$D:$D,"Optimizacion",Puntuacion!$G:$G,"<>NA")>0,1,0) | K3: =IF(AND(J3=1,COUNTIFS(Puntuacion!$A:$A,$A3,Puntuacion!$C:$C,$C3,Puntuacion!$D:$D,"Optimizacion",Puntuacion!$G:$G,"NE")=0),1,0) | L3: =IF(J3=0,"NA",IF(K3=0,"NE",AVERAGEIFS(Puntuacion!$G:$G,Puntuacion!$A:$A,$A3,Puntuacion!$C:$C,$C3,Puntuacion!$D:$D,"Optimizacion",Puntuacion!$G:$G,"<>NA",Puntuacion!$G:$G,"<>NE"))) | M3: =IF(COUNTIFS(Puntuacion!$A:$A,$A3,Puntuacion!$C:$C,$C3,Puntuacion!$D:$D,"Automatizacion",Puntuacion!$G:$G,"<>NA")>0,1,0) | N3: =IF(AND(M3=1,COUNTIFS(Puntuacion!$A:$A,$A3,Puntuacion!$C:$C,$C3,Puntuacion!$D:$D,"Automatizacion",Puntuacion!$G:$G,"NE")=0),1,0) | O3: =IF(M3=0,"NA",IF(N3=0,"NE",AVERAGEIFS(Puntuacion!$G:$G,Puntuacion!$A:$A,$A3,Puntuacion!$C:$C,$C3,Puntuacion!$D:$D,"Automatizacion",Puntuacion!$G:$G,"<>NA",Puntuacion!$G:$G,"<>NE"))) | P3: =IF(COUNTIFS(Puntuacion!$A:$A,$A3,Puntuacion!$C:$C,$C3,Puntuacion!$D:$D,"Multicloud",Puntuacion!$G:$G,"<>NA")>0,1,0) | Q3: =IF(AND(P3=1,COUNTIFS(Puntuacion!$A:$A,$A3,Puntuacion!$C:$C,$C3,Puntuacion!$D:$D,"Multicloud",Puntuacion!$G:$G,"NE")=0),1,0) | R3: =IF(P3=0,"NA",IF(Q3=0,"NE",AVERAGEIFS(Puntuacion!$G:$G,Puntuacion!$A:$A,$A3,Puntuacion!$C:$C,$C3,Puntuacion!$D:$D,"Multicloud",Puntuacion!$G:$G,"<>NA",Puntuacion!$G:$G,"<>NE"))) | S3: =IF(COUNTIFS(Puntuacion!$A:$A,$A3,Puntuacion!$C:$C,$C3,Puntuacion!$D:$D,"Integracion",Puntuacion!$G:$G,"<>NA")>0,1,0) | T3: =IF(AND(S3=1,COUNTIFS(Puntuacion!$A:$A,$A3,Puntuacion!$C:$C,$C3,Puntuacion!$D:$D,"Integracion",Puntuacion!$G:$G,"NE")=0),1,0) | U3: =IF(S3=0,"NA",IF(T3=0,"NE",AVERAGEIFS(Puntuacion!$G:$G,Puntuacion!$A:$A,$A3,Puntuacion!$C:$C,$C3,Puntuacion!$D:$D,"Integracion",Puntuacion!$G:$G,"<>NA",Puntuacion!$G:$G,"<>NE"))) | V3: =IF(COUNTIFS(Puntuacion!$A:$A,$A3,Puntuacion!$C:$C,$C3,Puntuacion!$D:$D,"Adopcion",Puntuacion!$G:$G,"<>NA")>0,1,0) | W3: =IF(AND(V3=1,COUNTIFS(Puntuacion!$A:$A,$A3,Puntuacion!$C:$C,$C3,Puntuacion!$D:$D,"Adopcion",Puntuacion!$G:$G,"NE")=0),1,0) | X3: =IF(V3=0,"NA",IF(W3=0,"NE",AVERAGEIFS(Puntuacion!$G:$G,Puntuacion!$A:$A,$A3,Puntuacion!$C:$C,$C3,Puntuacion!$D:$D,"Adopcion",Puntuacion!$G:$G,"<>NA",Puntuacion!$G:$G,"<>NE"))) | Y3: =IF(COUNTIFS(Puntuacion!$A:$A,$A3,Puntuacion!$C:$C,$C3,Puntuacion!$D:$D,"Precio",Puntuacion!$G:$G,"<>NA")>0,1,0) | Z3: =IF(AND(Y3=1,COUNTIFS(Puntuacion!$A:$A,$A3,Puntuacion!$C:$C,$C3,Puntuacion!$D:$D,"Precio",Puntuacion!$G:$G,"NE")=0),1,0) | AA3: =IF(Y3=0,"NA",IF(Z3=0,"NE",AVERAGEIFS(Puntuacion!$G:$G,Puntuacion!$A:$A,$A3,Puntuacion!$C:$C,$C3,Puntuacion!$D:$D,"Precio",Puntuacion!$G:$G,"<>NA",Puntuacion!$G:$G,"<>NE"))) | AB3: =IF(COUNTIFS(Puntuacion!$A:$A,$A3,Puntuacion!$C:$C,$C3,Puntuacion!$D:$D,"Dependencia",Puntuacion!$G:$G,"<>NA")>0,1,0) | AC3: =IF(AND(AB3=1,COUNTIFS(Puntuacion!$A:$A,$A3,Puntuacion!$C:$C,$C3,Puntuacion!$D:$D,"Dependencia",Puntuacion!$G:$G,"NE")=0),1,0) | AD3: =IF(AB3=0,"NA",IF(AC3=0,"NE",AVERAGEIFS(Puntuacion!$G:$G,Puntuacion!$A:$A,$A3,Puntuacion!$C:$C,$C3,Puntuacion!$D:$D,"Dependencia",Puntuacion!$G:$G,"<>NA",Puntuacion!$G:$G,"<>NE"))) | AE3: =IFERROR(100*(E3*Pesos!$B$2+H3*Pesos!$B$3+K3*Pesos!$B$4+N3*Pesos!$B$5+Q3*Pesos!$B$6+T3*Pesos!$B$7+W3*Pesos!$B$8+Z3*Pesos!$B$9+AC3*Pesos!$B$10)/(D3*Pesos!$B$2+G3*Pesos!$B$3+J3*Pesos!$B$4+M3*Pesos!$B$5+P3*Pesos!$B$6+S3*Pesos!$B$7+V3*Pesos!$B$8+Y3*Pesos!$B$9+AB3*Pesos!$B$10),"Sin criterios aplicables") | AF3: =IFERROR(100*(E3*Pesos!$C$2+H3*Pesos!$C$3+K3*Pesos!$C$4+N3*Pesos!$C$5+Q3*Pesos!$C$6+T3*Pesos!$C$7+W3*Pesos!$C$8+Z3*Pesos!$C$9+AC3*Pesos!$C$10)/(D3*Pesos!$C$2+G3*Pesos!$C$3+J3*Pesos!$C$4+M3*Pesos!$C$5+P3*Pesos!$C$6+S3*Pesos!$C$7+V3*Pesos!$C$8+Y3*Pesos!$C$9+AB3*Pesos!$C$10),"Sin criterios aplicables") | AG3: =IF(OR(AE3="Sin criterios aplicables",AE3<70),"Insufficient evidence",100*(Pesos!$B$2*IF(E3=1,F3,0)+Pesos!$B$3*IF(H3=1,I3,0)+Pesos!$B$4*IF(K3=1,L3,0)+Pesos!$B$5*IF(N3=1,O3,0)+Pesos!$B$6*IF(Q3=1,R3,0)+Pesos!$B$7*IF(T3=1,U3,0)+Pesos!$B$8*IF(W3=1,X3,0)+Pesos!$B$9*IF(Z3=1,AA3,0)+Pesos!$B$10*IF(AC3=1,AD3,0))/(3*(Pesos!$B$2*E3+Pesos!$B$3*H3+Pesos!$B$4*K3+Pesos!$B$5*N3+Pesos!$B$6*Q3+Pesos!$B$7*T3+Pesos!$B$8*W3+Pesos!$B$9*Z3+Pesos!$B$10*AC3))) | AH3: =IF(OR(AF3="Sin criterios aplicables",AF3<70),"Insufficient evidence",100*(Pesos!$C$2*IF(E3=1,F3,0)+Pesos!$C$3*IF(H3=1,I3,0)+Pesos!$C$4*IF(K3=1,L3,0)+Pesos!$C$5*IF(N3=1,O3,0)+Pesos!$C$6*IF(Q3=1,R3,0)+Pesos!$C$7*IF(T3=1,U3,0)+Pesos!$C$8*IF(W3=1,X3,0)+Pesos!$C$9*IF(Z3=1,AA3,0)+Pesos!$C$10*IF(AC3=1,AD3,0))/(3*(Pesos!$C$2*E3+Pesos!$C$3*H3+Pesos!$C$4*K3+Pesos!$C$5*N3+Pesos!$C$6*Q3+Pesos!$C$7*T3+Pesos!$C$8*W3+Pesos!$C$9*Z3+Pesos!$C$10*AC3))) | AI3: =IF(AG3="Insufficient evidence","Insufficient evidence (cobertura<70%)",IF(AG3<50/3,"Insufficient",IF(AG3<50,"Basic",IF(AG3<250/3,"Solid","Advanced")))) | AJ3: =IF(AH3="Insufficient evidence","Insufficient evidence (cobertura<70%)",IF(AH3<50/3,"Insufficient",IF(AH3<50,"Basic",IF(AH3<250/3,"Solid","Advanced")))) | AK3: =IF(TRIM(IF(AND(ISNUMBER(F3),F3<1),"Visibilidad","") & " " & IF(AND(ISNUMBER(I3),I3<1),"Asignación",""))="","Ninguno",TRIM(IF(AND(ISNUMBER(F3),F3<1),"Visibilidad","") & " " & IF(AND(ISNUMBER(I3),I3<1),"Asignación","")))
A4: E1 | B4: Cloud nativa | C4: Azure Cost Management | D4: =IF(COUNTIFS(Puntuacion!$A:$A,$A4,Puntuacion!$C:$C,$C4,Puntuacion!$D:$D,"Visibilidad",Puntuacion!$G:$G,"<>NA")>0,1,0) | E4: =IF(AND(D4=1,COUNTIFS(Puntuacion!$A:$A,$A4,Puntuacion!$C:$C,$C4,Puntuacion!$D:$D,"Visibilidad",Puntuacion!$G:$G,"NE")=0),1,0) | F4: =IF(D4=0,"NA",IF(E4=0,"NE",AVERAGEIFS(Puntuacion!$G:$G,Puntuacion!$A:$A,$A4,Puntuacion!$C:$C,$C4,Puntuacion!$D:$D,"Visibilidad",Puntuacion!$G:$G,"<>NA",Puntuacion!$G:$G,"<>NE"))) | G4: =IF(COUNTIFS(Puntuacion!$A:$A,$A4,Puntuacion!$C:$C,$C4,Puntuacion!$D:$D,"Asignacion",Puntuacion!$G:$G,"<>NA")>0,1,0) | H4: =IF(AND(G4=1,COUNTIFS(Puntuacion!$A:$A,$A4,Puntuacion!$C:$C,$C4,Puntuacion!$D:$D,"Asignacion",Puntuacion!$G:$G,"NE")=0),1,0) | I4: =IF(G4=0,"NA",IF(H4=0,"NE",AVERAGEIFS(Puntuacion!$G:$G,Puntuacion!$A:$A,$A4,Puntuacion!$C:$C,$C4,Puntuacion!$D:$D,"Asignacion",Puntuacion!$G:$G,"<>NA",Puntuacion!$G:$G,"<>NE"))) | J4: =IF(COUNTIFS(Puntuacion!$A:$A,$A4,Puntuacion!$C:$C,$C4,Puntuacion!$D:$D,"Optimizacion",Puntuacion!$G:$G,"<>NA")>0,1,0) | K4: =IF(AND(J4=1,COUNTIFS(Puntuacion!$A:$A,$A4,Puntuacion!$C:$C,$C4,Puntuacion!$D:$D,"Optimizacion",Puntuacion!$G:$G,"NE")=0),1,0) | L4: =IF(J4=0,"NA",IF(K4=0,"NE",AVERAGEIFS(Puntuacion!$G:$G,Puntuacion!$A:$A,$A4,Puntuacion!$C:$C,$C4,Puntuacion!$D:$D,"Optimizacion",Puntuacion!$G:$G,"<>NA",Puntuacion!$G:$G,"<>NE"))) | M4: =IF(COUNTIFS(Puntuacion!$A:$A,$A4,Puntuacion!$C:$C,$C4,Puntuacion!$D:$D,"Automatizacion",Puntuacion!$G:$G,"<>NA")>0,1,0) | N4: =IF(AND(M4=1,COUNTIFS(Puntuacion!$A:$A,$A4,Puntuacion!$C:$C,$C4,Puntuacion!$D:$D,"Automatizacion",Puntuacion!$G:$G,"NE")=0),1,0) | O4: =IF(M4=0,"NA",IF(N4=0,"NE",AVERAGEIFS(Puntuacion!$G:$G,Puntuacion!$A:$A,$A4,Puntuacion!$C:$C,$C4,Puntuacion!$D:$D,"Automatizacion",Puntuacion!$G:$G,"<>NA",Puntuacion!$G:$G,"<>NE"))) | P4: =IF(COUNTIFS(Puntuacion!$A:$A,$A4,Puntuacion!$C:$C,$C4,Puntuacion!$D:$D,"Multicloud",Puntuacion!$G:$G,"<>NA")>0,1,0) | Q4: =IF(AND(P4=1,COUNTIFS(Puntuacion!$A:$A,$A4,Puntuacion!$C:$C,$C4,Puntuacion!$D:$D,"Multicloud",Puntuacion!$G:$G,"NE")=0),1,0) | R4: =IF(P4=0,"NA",IF(Q4=0,"NE",AVERAGEIFS(Puntuacion!$G:$G,Puntuacion!$A:$A,$A4,Puntuacion!$C:$C,$C4,Puntuacion!$D:$D,"Multicloud",Puntuacion!$G:$G,"<>NA",Puntuacion!$G:$G,"<>NE"))) | S4: =IF(COUNTIFS(Puntuacion!$A:$A,$A4,Puntuacion!$C:$C,$C4,Puntuacion!$D:$D,"Integracion",Puntuacion!$G:$G,"<>NA")>0,1,0) | T4: =IF(AND(S4=1,COUNTIFS(Puntuacion!$A:$A,$A4,Puntuacion!$C:$C,$C4,Puntuacion!$D:$D,"Integracion",Puntuacion!$G:$G,"NE")=0),1,0) | U4: =IF(S4=0,"NA",IF(T4=0,"NE",AVERAGEIFS(Puntuacion!$G:$G,Puntuacion!$A:$A,$A4,Puntuacion!$C:$C,$C4,Puntuacion!$D:$D,"Integracion",Puntuacion!$G:$G,"<>NA",Puntuacion!$G:$G,"<>NE"))) | V4: =IF(COUNTIFS(Puntuacion!$A:$A,$A4,Puntuacion!$C:$C,$C4,Puntuacion!$D:$D,"Adopcion",Puntuacion!$G:$G,"<>NA")>0,1,0) | W4: =IF(AND(V4=1,COUNTIFS(Puntuacion!$A:$A,$A4,Puntuacion!$C:$C,$C4,Puntuacion!$D:$D,"Adopcion",Puntuacion!$G:$G,"NE")=0),1,0) | X4: =IF(V4=0,"NA",IF(W4=0,"NE",AVERAGEIFS(Puntuacion!$G:$G,Puntuacion!$A:$A,$A4,Puntuacion!$C:$C,$C4,Puntuacion!$D:$D,"Adopcion",Puntuacion!$G:$G,"<>NA",Puntuacion!$G:$G,"<>NE"))) | Y4: =IF(COUNTIFS(Puntuacion!$A:$A,$A4,Puntuacion!$C:$C,$C4,Puntuacion!$D:$D,"Precio",Puntuacion!$G:$G,"<>NA")>0,1,0) | Z4: =IF(AND(Y4=1,COUNTIFS(Puntuacion!$A:$A,$A4,Puntuacion!$C:$C,$C4,Puntuacion!$D:$D,"Precio",Puntuacion!$G:$G,"NE")=0),1,0) | AA4: =IF(Y4=0,"NA",IF(Z4=0,"NE",AVERAGEIFS(Puntuacion!$G:$G,Puntuacion!$A:$A,$A4,Puntuacion!$C:$C,$C4,Puntuacion!$D:$D,"Precio",Puntuacion!$G:$G,"<>NA",Puntuacion!$G:$G,"<>NE"))) | AB4: =IF(COUNTIFS(Puntuacion!$A:$A,$A4,Puntuacion!$C:$C,$C4,Puntuacion!$D:$D,"Dependencia",Puntuacion!$G:$G,"<>NA")>0,1,0) | AC4: =IF(AND(AB4=1,COUNTIFS(Puntuacion!$A:$A,$A4,Puntuacion!$C:$C,$C4,Puntuacion!$D:$D,"Dependencia",Puntuacion!$G:$G,"NE")=0),1,0) | AD4: =IF(AB4=0,"NA",IF(AC4=0,"NE",AVERAGEIFS(Puntuacion!$G:$G,Puntuacion!$A:$A,$A4,Puntuacion!$C:$C,$C4,Puntuacion!$D:$D,"Dependencia",Puntuacion!$G:$G,"<>NA",Puntuacion!$G:$G,"<>NE"))) | AE4: =IFERROR(100*(E4*Pesos!$B$2+H4*Pesos!$B$3+K4*Pesos!$B$4+N4*Pesos!$B$5+Q4*Pesos!$B$6+T4*Pesos!$B$7+W4*Pesos!$B$8+Z4*Pesos!$B$9+AC4*Pesos!$B$10)/(D4*Pesos!$B$2+G4*Pesos!$B$3+J4*Pesos!$B$4+M4*Pesos!$B$5+P4*Pesos!$B$6+S4*Pesos!$B$7+V4*Pesos!$B$8+Y4*Pesos!$B$9+AB4*Pesos!$B$10),"Sin criterios aplicables") | AF4: =IFERROR(100*(E4*Pesos!$C$2+H4*Pesos!$C$3+K4*Pesos!$C$4+N4*Pesos!$C$5+Q4*Pesos!$C$6+T4*Pesos!$C$7+W4*Pesos!$C$8+Z4*Pesos!$C$9+AC4*Pesos!$C$10)/(D4*Pesos!$C$2+G4*Pesos!$C$3+J4*Pesos!$C$4+M4*Pesos!$C$5+P4*Pesos!$C$6+S4*Pesos!$C$7+V4*Pesos!$C$8+Y4*Pesos!$C$9+AB4*Pesos!$C$10),"Sin criterios aplicables") | AG4: =IF(OR(AE4="Sin criterios aplicables",AE4<70),"Insufficient evidence",100*(Pesos!$B$2*IF(E4=1,F4,0)+Pesos!$B$3*IF(H4=1,I4,0)+Pesos!$B$4*IF(K4=1,L4,0)+Pesos!$B$5*IF(N4=1,O4,0)+Pesos!$B$6*IF(Q4=1,R4,0)+Pesos!$B$7*IF(T4=1,U4,0)+Pesos!$B$8*IF(W4=1,X4,0)+Pesos!$B$9*IF(Z4=1,AA4,0)+Pesos!$B$10*IF(AC4=1,AD4,0))/(3*(Pesos!$B$2*E4+Pesos!$B$3*H4+Pesos!$B$4*K4+Pesos!$B$5*N4+Pesos!$B$6*Q4+Pesos!$B$7*T4+Pesos!$B$8*W4+Pesos!$B$9*Z4+Pesos!$B$10*AC4))) | AH4: =IF(OR(AF4="Sin criterios aplicables",AF4<70),"Insufficient evidence",100*(Pesos!$C$2*IF(E4=1,F4,0)+Pesos!$C$3*IF(H4=1,I4,0)+Pesos!$C$4*IF(K4=1,L4,0)+Pesos!$C$5*IF(N4=1,O4,0)+Pesos!$C$6*IF(Q4=1,R4,0)+Pesos!$C$7*IF(T4=1,U4,0)+Pesos!$C$8*IF(W4=1,X4,0)+Pesos!$C$9*IF(Z4=1,AA4,0)+Pesos!$C$10*IF(AC4=1,AD4,0))/(3*(Pesos!$C$2*E4+Pesos!$C$3*H4+Pesos!$C$4*K4+Pesos!$C$5*N4+Pesos!$C$6*Q4+Pesos!$C$7*T4+Pesos!$C$8*W4+Pesos!$C$9*Z4+Pesos!$C$10*AC4))) | AI4: =IF(AG4="Insufficient evidence","Insufficient evidence (cobertura<70%)",IF(AG4<50/3,"Insufficient",IF(AG4<50,"Basic",IF(AG4<250/3,"Solid","Advanced")))) | AJ4: =IF(AH4="Insufficient evidence","Insufficient evidence (cobertura<70%)",IF(AH4<50/3,"Insufficient",IF(AH4<50,"Basic",IF(AH4<250/3,"Solid","Advanced")))) | AK4: =IF(TRIM(IF(AND(ISNUMBER(F4),F4<1),"Visibilidad","") & " " & IF(AND(ISNUMBER(I4),I4<1),"Asignación",""))="","Ninguno",TRIM(IF(AND(ISNUMBER(F4),F4<1),"Visibilidad","") & " " & IF(AND(ISNUMBER(I4),I4<1),"Asignación","")))
A5: E1 | B5: Cloud nativa | C5: Google Cloud Billing | D5: =IF(COUNTIFS(Puntuacion!$A:$A,$A5,Puntuacion!$C:$C,$C5,Puntuacion!$D:$D,"Visibilidad",Puntuacion!$G:$G,"<>NA")>0,1,0) | E5: =IF(AND(D5=1,COUNTIFS(Puntuacion!$A:$A,$A5,Puntuacion!$C:$C,$C5,Puntuacion!$D:$D,"Visibilidad",Puntuacion!$G:$G,"NE")=0),1,0) | F5: =IF(D5=0,"NA",IF(E5=0,"NE",AVERAGEIFS(Puntuacion!$G:$G,Puntuacion!$A:$A,$A5,Puntuacion!$C:$C,$C5,Puntuacion!$D:$D,"Visibilidad",Puntuacion!$G:$G,"<>NA",Puntuacion!$G:$G,"<>NE"))) | G5: =IF(COUNTIFS(Puntuacion!$A:$A,$A5,Puntuacion!$C:$C,$C5,Puntuacion!$D:$D,"Asignacion",Puntuacion!$G:$G,"<>NA")>0,1,0) | H5: =IF(AND(G5=1,COUNTIFS(Puntuacion!$A:$A,$A5,Puntuacion!$C:$C,$C5,Puntuacion!$D:$D,"Asignacion",Puntuacion!$G:$G,"NE")=0),1,0) | I5: =IF(G5=0,"NA",IF(H5=0,"NE",AVERAGEIFS(Puntuacion!$G:$G,Puntuacion!$A:$A,$A5,Puntuacion!$C:$C,$C5,Puntuacion!$D:$D,"Asignacion",Puntuacion!$G:$G,"<>NA",Puntuacion!$G:$G,"<>NE"))) | J5: =IF(COUNTIFS(Puntuacion!$A:$A,$A5,Puntuacion!$C:$C,$C5,Puntuacion!$D:$D,"Optimizacion",Puntuacion!$G:$G,"<>NA")>0,1,0) | K5: =IF(AND(J5=1,COUNTIFS(Puntuacion!$A:$A,$A5,Puntuacion!$C:$C,$C5,Puntuacion!$D:$D,"Optimizacion",Puntuacion!$G:$G,"NE")=0),1,0) | L5: =IF(J5=0,"NA",IF(K5=0,"NE",AVERAGEIFS(Puntuacion!$G:$G,Puntuacion!$A:$A,$A5,Puntuacion!$C:$C,$C5,Puntuacion!$D:$D,"Optimizacion",Puntuacion!$G:$G,"<>NA",Puntuacion!$G:$G,"<>NE"))) | M5: =IF(COUNTIFS(Puntuacion!$A:$A,$A5,Puntuacion!$C:$C,$C5,Puntuacion!$D:$D,"Automatizacion",Puntuacion!$G:$G,"<>NA")>0,1,0) | N5: =IF(AND(M5=1,COUNTIFS(Puntuacion!$A:$A,$A5,Puntuacion!$C:$C,$C5,Puntuacion!$D:$D,"Automatizacion",Puntuacion!$G:$G,"NE")=0),1,0) | O5: =IF(M5=0,"NA",IF(N5=0,"NE",AVERAGEIFS(Puntuacion!$G:$G,Puntuacion!$A:$A,$A5,Puntuacion!$C:$C,$C5,Puntuacion!$D:$D,"Automatizacion",Puntuacion!$G:$G,"<>NA",Puntuacion!$G:$G,"<>NE"))) | P5: =IF(COUNTIFS(Puntuacion!$A:$A,$A5,Puntuacion!$C:$C,$C5,Puntuacion!$D:$D,"Multicloud",Puntuacion!$G:$G,"<>NA")>0,1,0) | Q5: =IF(AND(P5=1,COUNTIFS(Puntuacion!$A:$A,$A5,Puntuacion!$C:$C,$C5,Puntuacion!$D:$D,"Multicloud",Puntuacion!$G:$G,"NE")=0),1,0) | R5: =IF(P5=0,"NA",IF(Q5=0,"NE",AVERAGEIFS(Puntuacion!$G:$G,Puntuacion!$A:$A,$A5,Puntuacion!$C:$C,$C5,Puntuacion!$D:$D,"Multicloud",Puntuacion!$G:$G,"<>NA",Puntuacion!$G:$G,"<>NE"))) | S5: =IF(COUNTIFS(Puntuacion!$A:$A,$A5,Puntuacion!$C:$C,$C5,Puntuacion!$D:$D,"Integracion",Puntuacion!$G:$G,"<>NA")>0,1,0) | T5: =IF(AND(S5=1,COUNTIFS(Puntuacion!$A:$A,$A5,Puntuacion!$C:$C,$C5,Puntuacion!$D:$D,"Integracion",Puntuacion!$G:$G,"NE")=0),1,0) | U5: =IF(S5=0,"NA",IF(T5=0,"NE",AVERAGEIFS(Puntuacion!$G:$G,Puntuacion!$A:$A,$A5,Puntuacion!$C:$C,$C5,Puntuacion!$D:$D,"Integracion",Puntuacion!$G:$G,"<>NA",Puntuacion!$G:$G,"<>NE"))) | V5: =IF(COUNTIFS(Puntuacion!$A:$A,$A5,Puntuacion!$C:$C,$C5,Puntuacion!$D:$D,"Adopcion",Puntuacion!$G:$G,"<>NA")>0,1,0) | W5: =IF(AND(V5=1,COUNTIFS(Puntuacion!$A:$A,$A5,Puntuacion!$C:$C,$C5,Puntuacion!$D:$D,"Adopcion",Puntuacion!$G:$G,"NE")=0),1,0) | X5: =IF(V5=0,"NA",IF(W5=0,"NE",AVERAGEIFS(Puntuacion!$G:$G,Puntuacion!$A:$A,$A5,Puntuacion!$C:$C,$C5,Puntuacion!$D:$D,"Adopcion",Puntuacion!$G:$G,"<>NA",Puntuacion!$G:$G,"<>NE"))) | Y5: =IF(COUNTIFS(Puntuacion!$A:$A,$A5,Puntuacion!$C:$C,$C5,Puntuacion!$D:$D,"Precio",Puntuacion!$G:$G,"<>NA")>0,1,0) | Z5: =IF(AND(Y5=1,COUNTIFS(Puntuacion!$A:$A,$A5,Puntuacion!$C:$C,$C5,Puntuacion!$D:$D,"Precio",Puntuacion!$G:$G,"NE")=0),1,0) | AA5: =IF(Y5=0,"NA",IF(Z5=0,"NE",AVERAGEIFS(Puntuacion!$G:$G,Puntuacion!$A:$A,$A5,Puntuacion!$C:$C,$C5,Puntuacion!$D:$D,"Precio",Puntuacion!$G:$G,"<>NA",Puntuacion!$G:$G,"<>NE"))) | AB5: =IF(COUNTIFS(Puntuacion!$A:$A,$A5,Puntuacion!$C:$C,$C5,Puntuacion!$D:$D,"Dependencia",Puntuacion!$G:$G,"<>NA")>0,1,0) | AC5: =IF(AND(AB5=1,COUNTIFS(Puntuacion!$A:$A,$A5,Puntuacion!$C:$C,$C5,Puntuacion!$D:$D,"Dependencia",Puntuacion!$G:$G,"NE")=0),1,0) | AD5: =IF(AB5=0,"NA",IF(AC5=0,"NE",AVERAGEIFS(Puntuacion!$G:$G,Puntuacion!$A:$A,$A5,Puntuacion!$C:$C,$C5,Puntuacion!$D:$D,"Dependencia",Puntuacion!$G:$G,"<>NA",Puntuacion!$G:$G,"<>NE"))) | AE5: =IFERROR(100*(E5*Pesos!$B$2+H5*Pesos!$B$3+K5*Pesos!$B$4+N5*Pesos!$B$5+Q5*Pesos!$B$6+T5*Pesos!$B$7+W5*Pesos!$B$8+Z5*Pesos!$B$9+AC5*Pesos!$B$10)/(D5*Pesos!$B$2+G5*Pesos!$B$3+J5*Pesos!$B$4+M5*Pesos!$B$5+P5*Pesos!$B$6+S5*Pesos!$B$7+V5*Pesos!$B$8+Y5*Pesos!$B$9+AB5*Pesos!$B$10),"Sin criterios aplicables") | AF5: =IFERROR(100*(E5*Pesos!$C$2+H5*Pesos!$C$3+K5*Pesos!$C$4+N5*Pesos!$C$5+Q5*Pesos!$C$6+T5*Pesos!$C$7+W5*Pesos!$C$8+Z5*Pesos!$C$9+AC5*Pesos!$C$10)/(D5*Pesos!$C$2+G5*Pesos!$C$3+J5*Pesos!$C$4+M5*Pesos!$C$5+P5*Pesos!$C$6+S5*Pesos!$C$7+V5*Pesos!$C$8+Y5*Pesos!$C$9+AB5*Pesos!$C$10),"Sin criterios aplicables") | AG5: =IF(OR(AE5="Sin criterios aplicables",AE5<70),"Insufficient evidence",100*(Pesos!$B$2*IF(E5=1,F5,0)+Pesos!$B$3*IF(H5=1,I5,0)+Pesos!$B$4*IF(K5=1,L5,0)+Pesos!$B$5*IF(N5=1,O5,0)+Pesos!$B$6*IF(Q5=1,R5,0)+Pesos!$B$7*IF(T5=1,U5,0)+Pesos!$B$8*IF(W5=1,X5,0)+Pesos!$B$9*IF(Z5=1,AA5,0)+Pesos!$B$10*IF(AC5=1,AD5,0))/(3*(Pesos!$B$2*E5+Pesos!$B$3*H5+Pesos!$B$4*K5+Pesos!$B$5*N5+Pesos!$B$6*Q5+Pesos!$B$7*T5+Pesos!$B$8*W5+Pesos!$B$9*Z5+Pesos!$B$10*AC5))) | AH5: =IF(OR(AF5="Sin criterios aplicables",AF5<70),"Insufficient evidence",100*(Pesos!$C$2*IF(E5=1,F5,0)+Pesos!$C$3*IF(H5=1,I5,0)+Pesos!$C$4*IF(K5=1,L5,0)+Pesos!$C$5*IF(N5=1,O5,0)+Pesos!$C$6*IF(Q5=1,R5,0)+Pesos!$C$7*IF(T5=1,U5,0)+Pesos!$C$8*IF(W5=1,X5,0)+Pesos!$C$9*IF(Z5=1,AA5,0)+Pesos!$C$10*IF(AC5=1,AD5,0))/(3*(Pesos!$C$2*E5+Pesos!$C$3*H5+Pesos!$C$4*K5+Pesos!$C$5*N5+Pesos!$C$6*Q5+Pesos!$C$7*T5+Pesos!$C$8*W5+Pesos!$C$9*Z5+Pesos!$C$10*AC5))) | AI5: =IF(AG5="Insufficient evidence","Insufficient evidence (cobertura<70%)",IF(AG5<50/3,"Insufficient",IF(AG5<50,"Basic",IF(AG5<250/3,"Solid","Advanced")))) | AJ5: =IF(AH5="Insufficient evidence","Insufficient evidence (cobertura<70%)",IF(AH5<50/3,"Insufficient",IF(AH5<50,"Basic",IF(AH5<250/3,"Solid","Advanced")))) | AK5: =IF(TRIM(IF(AND(ISNUMBER(F5),F5<1),"Visibilidad","") & " " & IF(AND(ISNUMBER(I5),I5<1),"Asignación",""))="","Ninguno",TRIM(IF(AND(ISNUMBER(F5),F5<1),"Visibilidad","") & " " & IF(AND(ISNUMBER(I5),I5<1),"Asignación","")))
